Workbook

Sheet Détails
A1: SCPI Fair Invest
A3: Données d'une part
A5: Prix part | C5: 181.5 | D5: 202
A6: dont droits et frais | C6: 14 | D6: 14
A7: dont frais collecte | C7: 4.5833333 | D7: 20
A9: Délai de jouissance | C9: 4 | D9: mois
C10: 6 | D10: mois
A13: Données souscription
A15: Profil | C15: =+Résumé!F2 -> Non Fondateur
A16: Catégorie | C16: Pleine Propriété
A17: Durée de souscription | C17: =+Résumé!F3 -> 10
A18: Montant de souscription | C18: =+C26*Résumé!F4 -> 10100
A19: Recurring | C19: =C26*Résumé!F5 -> 404
A23: Résumé de souscription
A25: Montant de souscription | C25: =C18 -> 10100 | I25: Investissement | J25: Gains | K25: TRI
A26: Prix d'une part | C26: =+IF($C$15="fondateur",C5,D5) -> 202
A27: dont droits et frais | C27: =+IF($C$15="fondateur",C6,D6) -> 14 | H27: =+C16 -> Pleine Propriété | I27: =+C49 -> 46803.789 | J27: =+C65 -> 14385.94 | K27: =+XIRR(D65:IW65,D64:IW64) -> 0.039029887
A28: dont frais collecte | C28: =+IF($C$15="fondateur",C7,D7) -> 20
A29: Nombre de parts | C29: =+C18/C26 -> 50
A31: Profil | C31: =+C15 -> Non Fondateur | J31: =2+1 -> 3 | K31: =+J31+1 -> 4 | L31: =+K31+1 -> 5 | M31: =+L31+1 -> 6 | N31: =+M31+1 -> 7 | O31: =+N31+1 -> 8 | P31: =+O31+1 -> 9 | Q31: =+P31+1 -> 10 | R31: =+Q31+1 -> 11 | ... AB31: =+AA31+1 -> 21
A32: Durée de souscription | C32: =+C17 -> 10 | I32: =+K27 -> 0.039029887 | J32: #REF! | K32: #REF! | L32: #REF! | M32: #REF! | N32: #REF! | O32: 0.034366289 | P32: 0.038743731 | Q32: 0.041718391 | R32: 0.043862954 | S32: 0.045453891 | T32: 0.046663108 | U32: 0.047588769 | V32: 0.048321977 | W32: 0.048901322 | X32: 0.04936147 | Y32: 0.046696177 | Z32: 0.045964125 | AA32: 0.045416412 | AB32: 0.045060536
A33: Catégorie | C33: =+C16 -> Pleine Propriété
A34: DVM | C34: =+Résumé!F7 -> 0.0472 | J34: =2+1 -> 3 | K34: =+J34+1 -> 4 | L34: =+K34+1 -> 5 | M34: =+L34+1 -> 6 | N34: =+M34+1 -> 7 | O34: =+N34+1 -> 8 | P34: =+O34+1 -> 9 | Q34: =+P34+1 -> 10 | R34: =+Q34+1 -> 11 | ... AB34: =+AA34+1 -> 21
A35: Valeur de la part pour calcul du rendement | C35: =+D5 -> 202 | I35: =+J27 -> 14385.94 | J35: #REF! | K35: #REF! | L35: #REF! | M35: #REF! | N35: #REF! | O35: 8854.3553 | P35: 12223.619 | Q35: 15605.198 | R35: 18999.278 | S35: 22406.046 | T35: 25825.692 | U35: 29258.411 | V35: 32704.397 | W35: 36163.85 | X35: 39636.971 | Y35: 40790.485 | Z35: 46235.894 | AA35: 53124.883 | AB35: 61607.739
A36: Valeur de la part pour calcul de sortie | C36: =+C26-C28 -> 182
A37: Revalorisation d'une part | C37: =+Résumé!F8 -> 0.01 | J37: =2+1 -> 3 | K37: =+J37+1 -> 4 | L37: =+K37+1 -> 5 | M37: =+L37+1 -> 6 | N37: =+M37+1 -> 7 | O37: =+N37+1 -> 8 | P37: =+O37+1 -> 9 | Q37: =+P37+1 -> 10 | R37: =+Q37+1 -> 11 | ... AB37: =+AA37+1 -> 21 | CV37: =200*(1+1%)^(8-1) -> 214.42707
I38: =+C43 -> 61189.729 | J38: #REF! | K38: #REF! | L38: #REF! | M38: #REF! | N38: #REF! | O38: 56224.417 | P38: 59593.681 | Q38: 62975.26 | R38: 66369.34 | S38: 69776.108 | T38: 73195.754 | U38: 76628.473 | V38: 80074.459 | W38: 83533.912 | X38: 87007.033 | Y38: 94335.431 | Z38: 112131.98 | AA38: 131376.21 | AB38: 152221.15
A39: CF
A41: Disponible dans le wallet client début du mois | C41: =SUM(D41:XEG41) -> 121678.31 | E41: =+IF(E$63>$C$17,0,D46) -> 0 | F41: =+IF(F$63>$C$17,0,E46) -> 0 | G41: =+IF(G$63>$C$17,0,F46) -> 0 | H41: =+IF(H$63>$C$17,0,G46) -> 0 | I41: =+IF(I$63>$C$17,0,H46) -> 0 | J41: =+IF(J$63>$C$17,0,I46) -> 39.726667 | K41: =+IF(K$63>$C$17,0,J46) -> 81.0424 | L41: =+IF(L$63>$C$17,0,K46) -> 123.9472 | ... IV41: =+IF(IV$63>$C$17,0,IU46) -> 0
A42: Profit périodique | C42: =SUM(D42:XEG42) -> 70873.172 | E42: =+SUM(OFFSET(E66,0,0,COUNTA($D$42:D42)+1)) -> 0 | F42: =+SUM(OFFSET(F66,0,0,COUNTA($D$42:E42)+1)) -> 0 | G42: =+SUM(OFFSET(G66,0,0,COUNTA($D$42:F42)+1)) -> 0 | H42: =+SUM(OFFSET(H66,0,0,COUNTA($D$42:G42)+1)) -> 0 | I42: =+SUM(OFFSET(I66,0,0,COUNTA($D$42:H42)+1)) -> 39.726667 | J42: =+SUM(OFFSET(J66,0,0,COUNTA($D$42:I42)+1)) -> 41.315733 | K42: =+SUM(OFFSET(K66,0,0,COUNTA($D$42:J42)+1)) -> 42.9048 | L42: =+SUM(OFFSET(L66,0,0,COUNTA($D$42:K42)+1)) -> 44.493867 | ... IV42: =+SUM(OFFSET(IV66,0,0,COUNTA($D$42:IU42)+1)) -> 0
A43: Disponible dans le wallet client fin du mois (avant souscription du mois) | C43: =+MAX(E43:IV43) -> 61189.729 | E43: =+IF(E$63>$C$17,0,E42+D43-D44) -> 0 | F43: =+IF(F$63>$C$17,0,F42+E43-E44) -> 0 | G43: =+IF(G$63>$C$17,0,G42+F43-F44) -> 0 | H43: =+IF(H$63>$C$17,0,H42+G43-G44) -> 0 | I43: =+IF(I$63>$C$17,0,I42+H43-H44) -> 39.726667 | J43: =+IF(J$63>$C$17,0,J42+I43-I44) -> 81.0424 | K43: =+IF(K$63>$C$17,0,K42+J43-J44) -> 123.9472 | L43: =+IF(L$63>$C$17,0,L42+K43-K44) -> 168.44107 | ... IV43: =+IF(IV$63>$C$17,0,IV42+IU43-IU44) -> 0
A44: Nouvelles souscriptions (montant payé) | C44: =SUM(D44:XEG44) -> 9683.4429 | E44: =+E45*E58 -> 0 | F44: =+F45*F58 -> 0 | G44: =+G45*G58 -> 0 | H44: =+H45*H58 -> 0 | I44: =+I45*I58 -> 0 | J44: =+J45*J58 -> 0 | K44: =+K45*K58 -> 0 | L44: =+L45*L58 -> 0 | ... IV44: =+IV45*IV58 -> 0
A45: Nouvelles souscriptions (nb de parts) | C45: =SUM(D45:XEG45) -> 46 | E45: =+IF(Résumé!$F$6="oui",IF(OFFSET(F$63,,$A$63)>$C$17,0,IF(F$63>$C$17,0,ROUNDDOWN(E43/E58,0))),0) -> 0 | F45: =+IF(Résumé!$F$6="oui",IF(OFFSET(G$63,,$A$63)>$C$17,0,IF(G$63>$C$17,0,ROUNDDOWN(F43/F58,0))),0) -> 0 | G45: =+IF(Résumé!$F$6="oui",IF(OFFSET(H$63,,$A$63)>$C$17,0,IF(H$63>$C$17,0,ROUNDDOWN(G43/G58,0))),0) -> 0 | H45: =+IF(Résumé!$F$6="oui",IF(OFFSET(I$63,,$A$63)>$C$17,0,IF(I$63>$C$17,0,ROUNDDOWN(H43/H58,0))),0) -> 0 | I45: =+IF(Résumé!$F$6="oui",IF(OFFSET(J$63,,$A$63)>$C$17,0,IF(J$63>$C$17,0,ROUNDDOWN(I43/I58,0))),0) -> 0 | J45: =+IF(Résumé!$F$6="oui",IF(OFFSET(K$63,,$A$63)>$C$17,0,IF(K$63>$C$17,0,ROUNDDOWN(J43/J58,0))),0) -> 0 | K45: =+IF(Résumé!$F$6="oui",IF(OFFSET(L$63,,$A$63)>$C$17,0,IF(L$63>$C$17,0,ROUNDDOWN(K43/K58,0))),0) -> 0 | L45: =+IF(Résumé!$F$6="oui",IF(OFFSET(M$63,,$A$63)>$C$17,0,IF(M$63>$C$17,0,ROUNDDOWN(L43/L58,0))),0) -> 0 | ... IV45: =+IF(Résumé!$F$6="oui",IF(OFFSET(IW$63,,$A$63)>$C$17,0,IF(IW$63>$C$17,0,ROUNDDOWN(IV43/IV58,0))),0) -> 0
A46: Disponible dans le wallet client fin du mois (après souscription du mois) | C46: =+IV46 -> 0 | E46: =+E43-E44 -> 0 | F46: =+F43-F44 -> 0 | G46: =+G43-G44 -> 0 | H46: =+H43-H44 -> 0 | I46: =+I43-I44 -> 39.726667 | J46: =+J43-J44 -> 81.0424 | K46: =+K43-K44 -> 123.9472 | L46: =+L43-L44 -> 168.44107 | ... IV46: =+IV43-IV44 -> 0
A47: Check | C47: {=+E47:IV47=TRUE} -> TRUE | E47: =+AND(ROUND(E41+E42-E44,2)=ROUND(E46,2),ROUND(E41+E42,2)=ROUND(E43,2)) -> TRUE | F47: =+AND(ROUND(F41+F42-F44,2)=ROUND(F46,2),ROUND(F41+F42,2)=ROUND(F43,2)) -> TRUE | G47: =+AND(ROUND(G41+G42-G44,2)=ROUND(G46,2),ROUND(G41+G42,2)=ROUND(G43,2)) -> TRUE | H47: =+AND(ROUND(H41+H42-H44,2)=ROUND(H46,2),ROUND(H41+H42,2)=ROUND(H43,2)) -> TRUE | I47: =+AND(ROUND(I41+I42-I44,2)=ROUND(I46,2),ROUND(I41+I42,2)=ROUND(I43,2)) -> TRUE | J47: =+AND(ROUND(J41+J42-J44,2)=ROUND(J46,2),ROUND(J41+J42,2)=ROUND(J43,2)) -> TRUE | K47: =+AND(ROUND(K41+K42-K44,2)=ROUND(K46,2),ROUND(K41+K42,2)=ROUND(K43,2)) -> TRUE | L47: =+AND(ROUND(L41+L42-L44,2)=ROUND(L46,2),ROUND(L41+L42,2)=ROUND(L43,2)) -> TRUE | ... IV47: =+AND(ROUND(IV41+IV42-IV44,2)=ROUND(IV46,2),ROUND(IV41+IV42,2)=ROUND(IV43,2)) -> TRUE
A49: Souscription Initiale + récurrente (montant payé) | C49: =SUM(D49:XEG49) -> 46803.789 | D49: =+D50*Détails!$D$58 -> 10100 | E49: =IF(F$63>$C$17,0,E50*E$58) -> 404 | F49: =IF(G$63>$C$17,0,F50*F$58) -> 404 | G49: =IF(H$63>$C$17,0,G50*G$58) -> 404 | H49: =IF(I$63>$C$17,0,H50*H$58) -> 404 | I49: =IF(J$63>$C$17,0,I50*I$58) -> 404 | J49: =IF(K$63>$C$17,0,J50*J$58) -> 404 | K49: =IF(L$63>$C$17,0,K50*K$58) -> 404 | L49: =IF(M$63>$C$17,0,L50*L$58) -> 404 | ... IV49: =IF(IW$63>$C$17,0,IV50*IV$58) -> 0
A50: Souscription Initiale + récurrente (nb de parts) | C50: =SUM(D50:XEG50) -> 226 | D50: =+Résumé!$F$4 -> 50 | E50: =IF(OR(OFFSET(F$63,,$A$63)>$C$17,F$63>$C$17),0,Résumé!$F$5) -> 2 | F50: =IF(OR(OFFSET(G$63,,$A$63)>$C$17,G$63>$C$17),0,Résumé!$F$5) -> 2 | G50: =IF(OR(OFFSET(H$63,,$A$63)>$C$17,H$63>$C$17),0,Résumé!$F$5) -> 2 | H50: =IF(OR(OFFSET(I$63,,$A$63)>$C$17,I$63>$C$17),0,Résumé!$F$5) -> 2 | I50: =IF(OR(OFFSET(J$63,,$A$63)>$C$17,J$63>$C$17),0,Résumé!$F$5) -> 2 | J50: =IF(OR(OFFSET(K$63,,$A$63)>$C$17,K$63>$C$17),0,Résumé!$F$5) -> 2 | K50: =IF(OR(OFFSET(L$63,,$A$63)>$C$17,L$63>$C$17),0,Résumé!$F$5) -> 2 | L50: =IF(OR(OFFSET(M$63,,$A$63)>$C$17,M$63>$C$17),0,Résumé!$F$5) -> 2 | ... IV50: =IF(OR(OFFSET(IW$63,,$A$63)>$C$17,IW$63>$C$17),0,Résumé!$F$5) -> 0
A52: Souscription totale (nb de parts) | C52: =SUM(D52:XEG52) -> 272 | D52: =+D50+D45 -> 50 | E52: =+E50+E45 -> 2 | F52: =+F50+F45 -> 2 | G52: =+G50+G45 -> 2 | H52: =+H50+H45 -> 2 | I52: =+I50+I45 -> 2 | J52: =+J50+J45 -> 2 | K52: =+K50+K45 -> 2 | ... IV52: =+IV50+IV45 -> 0
A53: Souscription totale (montant payé) | C53: =SUM(D53:XEG53) -> 56487.232 | D53: =+D49+D44 -> 10100 | E53: =+E49+E44 -> 404 | F53: =+F49+F44 -> 404 | G53: =+G49+G44 -> 404 | H53: =+H49+H44 -> 404 | I53: =+I49+I44 -> 404 | J53: =+J49+J44 -> 404 | K53: =+K49+K44 -> 404 | ... IV53: =+IV49+IV44 -> 0
A55: zakat | B55: 0.02579 | C55: =SUM(D55:XEG55) -> 6158.8107 | P55: =IF((OFFSET(Q$63,,$A$63)-1)>$C$17,0,$B$55*P56) -> 385.50892 | AB55: =IF((OFFSET(AC$63,,$A$63)-1)>$C$17,0,$B$55*AB56) -> 501.84686 | AN55: =IF((OFFSET(AO$63,,$A$63)-1)>$C$17,0,$B$55*AN56) -> 616.44725 | AZ55: =IF((OFFSET(BA$63,,$A$63)-1)>$C$17,0,$B$55*AZ56) -> 729.36753 | BL55: =IF((OFFSET(BM$63,,$A$63)-1)>$C$17,0,$B$55*BL56) -> 840.66378 | BX55: =IF((OFFSET(BY$63,,$A$63)-1)>$C$17,0,$B$55*BX56) -> 950.39076 | CJ55: =IF((OFFSET(CK$63,,$A$63)-1)>$C$17,0,$B$55*CJ56) -> 1058.602 | CV55: =IF((OFFSET(CW$63,,$A$63)-1)>$C$17,0,$B$55*CV56) -> 1075.9836 | DH55: =IF((OFFSET(DI$63,,$A$63)-1)>$C$17,0,$B$55*DH56) -> 0 | DT55: =IF((OFFSET(DU$63,,$A$63)-1)>$C$17,0,$B$55*DT56) -> 0 | EF55: =IF((OFFSET(EG$63,,$A$63)-1)>$C$17,0,$B$55*EF56) -> 0 | ER55: =IF((OFFSET(ES$63,,$A$63)-1)>$C$17,0,$B$55*ER56) -> 0 | FD55: =IF((OFFSET(FE$63,,$A$63)-1)>$C$17,0,$B$55*FD56) -> 0 | FP55: =IF((OFFSET(FQ$63,,$A$63)-1)>$C$17,0,$B$55*FP56) -> 0 | GB55: =IF((OFFSET(GC$63,,$A$63)-1)>$C$17,0,$B$55*GB56) -> 0 | GN55: =IF((OFFSET(GO$63,,$A$63)-1)>$C$17,0,$B$55*GN56) -> 0 | GZ55: =IF((OFFSET(HA$63,,$A$63)-1)>$C$17,0,$B$55*GZ56) -> 0 | HL55: =IF((OFFSET(HM$63,,$A$63)-1)>$C$17,0,$B$55*HL56) -> 0 | HX55: =IF((OFFSET(HY$63,,$A$63)-1)>$C$17,0,$B$55*HX56) -> 0 | IJ55: =IF((OFFSET(IK$63,,$A$63)-1)>$C$17,0,$B$55*IJ56) -> 0 | IV55: =IF((OFFSET(IW$63,,$A$63)-1)>$C$17,0,$B$55*IV56) -> 0
...

Sheet Détails (2)
A1: SCPI Fair Invest
A3: Données d'une part
A5: Prix part | C5: 181.5 | D5: 200
A6: dont droits et frais | C6: 14 | D6: 14
A7: dont frais collecte | C7: 5.5 | D7: 24
A9: Délai de jouissance | C9: 4 | D9: mois
C10: 6 | D10: mois
A13: Données souscription
A15: Profil | C15: =+Résumé!F2 -> Non Fondateur
A16: Catégorie | C16: Pleine Propriété
A17: Durée de souscription | C17: =+Résumé!F3 -> 10
A18: Montant de souscription | C18: =+C26*Résumé!F4 -> 10000
A19: Recurring | C19: =C26*Résumé!F5 -> 400
A23: Résumé de souscription
A25: Montant de souscription | C25: =C18 -> 10000 | I25: Investissement | J25: Gains | K25: TRI
A26: Prix d'une part | C26: =+IF($C$15="fondateur",C5,D5) -> 200
A27: dont droits et frais | C27: =+IF($C$15="fondateur",C6,D6) -> 14 | H27: =+C16 -> Pleine Propriété | I27: =+C49 -> 59781.146 | J27: =+C65 -> 11606.533 | K27: =+XIRR(D65:IW65,D64:IW64) -> 0.030468085
A28: dont frais collecte | C28: =+IF($C$15="fondateur",C7,D7) -> 24
A29: Nombre de parts | C29: =+C18/C26 -> 50
A31: Profil | C31: =+C15 -> Non Fondateur
A32: Durée de souscription | C32: =+C17 -> 10
A33: Catégorie | C33: =+C16 -> Pleine Propriété
A34: DVM | C34: =+Résumé!F7 -> 0.0472
A35: Valeur de la part pour calcul du rendement | C35: =+D5 -> 200
A36: Valeur de la part pour calcul de sortie | C36: =+C26-C28 -> 176
A37: Revalorisation d'une part | C37: =+Résumé!F8 -> 0.01 | CV37: =200*(1+1%)^(8-1) -> 214.42707
A39: CF
A41: Disponible dans le wallet client début du mois | C41: =SUM(D41:XEG41) -> 12347.399 | E41: =+IF(E$63>$C$17,0,D46) -> 0 | F41: =+IF(F$63>$C$17,0,E46) -> 0 | G41: =+IF(G$63>$C$17,0,F46) -> 0 | H41: =+IF(H$63>$C$17,0,G46) -> 0 | I41: =+IF(I$63>$C$17,0,H46) -> 0 | J41: =+IF(J$63>$C$17,0,I46) -> 39.333333 | K41: =+IF(K$63>$C$17,0,J46) -> 80.24 | L41: =+IF(L$63>$C$17,0,K46) -> 122.72 | ... IV41: =+IF(IV$63>$C$17,0,IU46) -> 0
A42: Profit périodique | C42: =SUM(D42:XEG42) -> 88566.243 | E42: =+SUM(OFFSET(E66,0,0,COUNTA($D$42:D42)+1)) -> 0 | F42: =+SUM(OFFSET(F66,0,0,COUNTA($D$42:E42)+1)) -> 0 | G42: =+SUM(OFFSET(G66,0,0,COUNTA($D$42:F42)+1)) -> 0 | H42: =+SUM(OFFSET(H66,0,0,COUNTA($D$42:G42)+1)) -> 0 | I42: =+SUM(OFFSET(I66,0,0,COUNTA($D$42:H42)+1)) -> 39.333333 | J42: =+SUM(OFFSET(J66,0,0,COUNTA($D$42:I42)+1)) -> 40.906667 | K42: =+SUM(OFFSET(K66,0,0,COUNTA($D$42:J42)+1)) -> 42.48 | L42: =+SUM(OFFSET(L66,0,0,COUNTA($D$42:K42)+1)) -> 44.053333 | ... IV42: =+SUM(OFFSET(IV66,0,0,COUNTA($D$42:IU42)+1)) -> 0
A43: Disponible dans le wallet client fin du mois (avant souscription du mois) | C43: =+MAX(E43:IV43) -> 71387.679 | E43: =+IF(E$63>$C$17,0,E42+D43-D44) -> 0 | F43: =+IF(F$63>$C$17,0,F42+E43-E44) -> 0 | G43: =+IF(G$63>$C$17,0,G42+F43-F44) -> 0 | H43: =+IF(H$63>$C$17,0,H42+G43-G44) -> 0 | I43: =+IF(I$63>$C$17,0,I42+H43-H44) -> 39.333333 | J43: =+IF(J$63>$C$17,0,J42+I43-I44) -> 80.24 | K43: =+IF(K$63>$C$17,0,K42+J43-J44) -> 122.72 | L43: =+IF(L$63>$C$17,0,L42+K43-K44) -> 166.77333 | ... IV43: =+IF(IV$63>$C$17,0,IV42+IU43-IU44) -> 0
A44: Nouvelles souscriptions (montant payé) | C44: =SUM(D44:XEG44) -> 17178.564 | E44: =+E45*E58 -> 0 | F44: =+F45*F58 -> 0 | G44: =+G45*G58 -> 0 | H44: =+H45*H58 -> 0 | I44: =+I45*I58 -> 0 | J44: =+J45*J58 -> 0 | K44: =+K45*K58 -> 0 | L44: =+L45*L58 -> 0 | ... IV44: =+IV45*IV58 -> 0
A45: Nouvelles souscriptions (nb de parts) | C45: =SUM(D45:XEG45) -> 81 | E45: =+IF(Résumé!$F$6="oui",IF(OFFSET(F$63,,$A$63)>$C$17,0,IF(F$63>$C$17,0,ROUNDDOWN(E43/E58,0))),0) -> 0 | F45: =+IF(Résumé!$F$6="oui",IF(OFFSET(G$63,,$A$63)>$C$17,0,IF(G$63>$C$17,0,ROUNDDOWN(F43/F58,0))),0) -> 0 | G45: =+IF(Résumé!$F$6="oui",IF(OFFSET(H$63,,$A$63)>$C$17,0,IF(H$63>$C$17,0,ROUNDDOWN(G43/G58,0))),0) -> 0 | H45: =+IF(Résumé!$F$6="oui",IF(OFFSET(I$63,,$A$63)>$C$17,0,IF(I$63>$C$17,0,ROUNDDOWN(H43/H58,0))),0) -> 0 | I45: =+IF(Résumé!$F$6="oui",IF(OFFSET(J$63,,$A$63)>$C$17,0,IF(J$63>$C$17,0,ROUNDDOWN(I43/I58,0))),0) -> 0 | J45: =+IF(Résumé!$F$6="oui",IF(OFFSET(K$63,,$A$63)>$C$17,0,IF(K$63>$C$17,0,ROUNDDOWN(J43/J58,0))),0) -> 0 | K45: =+IF(Résumé!$F$6="oui",IF(OFFSET(L$63,,$A$63)>$C$17,0,IF(L$63>$C$17,0,ROUNDDOWN(K43/K58,0))),0) -> 0 | L45: =+IF(Résumé!$F$6="oui",IF(OFFSET(M$63,,$A$63)>$C$17,0,IF(M$63>$C$17,0,ROUNDDOWN(L43/L58,0))),0) -> 0 | ... IV45: =+IF(Résumé!$F$6="oui",IF(OFFSET(IW$63,,$A$63)>$C$17,0,IF(IW$63>$C$17,0,ROUNDDOWN(IV43/IV58,0))),0) -> 0
A46: Disponible dans le wallet client fin du mois (après souscription du mois) | C46: =+IV46 -> 0 | E46: =+E43-E44 -> 0 | F46: =+F43-F44 -> 0 | G46: =+G43-G44 -> 0 | H46: =+H43-H44 -> 0 | I46: =+I43-I44 -> 39.333333 | J46: =+J43-J44 -> 80.24 | K46: =+K43-K44 -> 122.72 | L46: =+L43-L44 -> 166.77333 | ... IV46: =+IV43-IV44 -> 0
A47: Check | C47: {=+E47:IV47=TRUE} -> TRUE | E47: =+AND(ROUND(E41+E42-E44,2)=ROUND(E46,2),ROUND(E41+E42,2)=ROUND(E43,2)) -> TRUE | F47: =+AND(ROUND(F41+F42-F44,2)=ROUND(F46,2),ROUND(F41+F42,2)=ROUND(F43,2)) -> TRUE | G47: =+AND(ROUND(G41+G42-G44,2)=ROUND(G46,2),ROUND(G41+G42,2)=ROUND(G43,2)) -> TRUE | H47: =+AND(ROUND(H41+H42-H44,2)=ROUND(H46,2),ROUND(H41+H42,2)=ROUND(H43,2)) -> TRUE | I47: =+AND(ROUND(I41+I42-I44,2)=ROUND(I46,2),ROUND(I41+I42,2)=ROUND(I43,2)) -> TRUE | J47: =+AND(ROUND(J41+J42-J44,2)=ROUND(J46,2),ROUND(J41+J42,2)=ROUND(J43,2)) -> TRUE | K47: =+AND(ROUND(K41+K42-K44,2)=ROUND(K46,2),ROUND(K41+K42,2)=ROUND(K43,2)) -> TRUE | L47: =+AND(ROUND(L41+L42-L44,2)=ROUND(L46,2),ROUND(L41+L42,2)=ROUND(L43,2)) -> TRUE | ... IV47: =+AND(ROUND(IV41+IV42-IV44,2)=ROUND(IV46,2),ROUND(IV41+IV42,2)=ROUND(IV43,2)) -> TRUE
A49: Souscription Initiale + récurrente (montant payé) | C49: =SUM(D49:XEG49) -> 59781.146 | D49: =+D50*'Détails (2)'!$D$58 -> 10000 | E49: =IF(F$63>$C$17,0,E50*E$58) -> 400 | F49: =IF(G$63>$C$17,0,F50*F$58) -> 400 | G49: =IF(H$63>$C$17,0,G50*G$58) -> 400 | H49: =IF(I$63>$C$17,0,H50*H$58) -> 400 | I49: =IF(J$63>$C$17,0,I50*I$58) -> 400 | J49: =IF(K$63>$C$17,0,J50*J$58) -> 400 | K49: =IF(L$63>$C$17,0,K50*K$58) -> 400 | L49: =IF(M$63>$C$17,0,L50*L$58) -> 400 | ... IV49: =IF(IW$63>$C$17,0,IV50*IV$58) -> 0
A50: Souscription Initiale + récurrente (nb de parts) | C50: =SUM(D50:XEG50) -> 288 | D50: =+Résumé!$F$4 -> 50 | E50: =IF(OR(OFFSET(F$63,,$A$63)>$C$17,F$63>$C$17),0,Résumé!$F$5) -> 2 | F50: =IF(OR(OFFSET(G$63,,$A$63)>$C$17,G$63>$C$17),0,Résumé!$F$5) -> 2 | G50: =IF(OR(OFFSET(H$63,,$A$63)>$C$17,H$63>$C$17),0,Résumé!$F$5) -> 2 | H50: =IF(OR(OFFSET(I$63,,$A$63)>$C$17,I$63>$C$17),0,Résumé!$F$5) -> 2 | I50: =IF(OR(OFFSET(J$63,,$A$63)>$C$17,J$63>$C$17),0,Résumé!$F$5) -> 2 | J50: =IF(OR(OFFSET(K$63,,$A$63)>$C$17,K$63>$C$17),0,Résumé!$F$5) -> 2 | K50: =IF(OR(OFFSET(L$63,,$A$63)>$C$17,L$63>$C$17),0,Résumé!$F$5) -> 2 | L50: =IF(OR(OFFSET(M$63,,$A$63)>$C$17,M$63>$C$17),0,Résumé!$F$5) -> 2 | ... IV50: =IF(OR(OFFSET(IW$63,,$A$63)>$C$17,IW$63>$C$17),0,Résumé!$F$5) -> 0
A52: Souscription totale (nb de parts) | C52: =SUM(D52:XEG52) -> 369 | D52: =+D50+D45 -> 50 | E52: =+E50+E45 -> 2 | F52: =+F50+F45 -> 2 | G52: =+G50+G45 -> 2 | H52: =+H50+H45 -> 2 | I52: =+I50+I45 -> 2 | J52: =+J50+J45 -> 2 | K52: =+K50+K45 -> 2 | ... IV52: =+IV50+IV45 -> 0
A53: Souscription totale (montant payé) | C53: =SUM(D53:XEG53) -> 76959.71 | D53: =+D49+D44 -> 10000 | E53: =+E49+E44 -> 400 | F53: =+F49+F44 -> 400 | G53: =+G49+G44 -> 400 | H53: =+H49+H44 -> 400 | I53: =+I49+I44 -> 400 | J53: =+J49+J44 -> 400 | K53: =+K49+K44 -> 400 | ... IV53: =+IV49+IV44 -> 0
A55: zakat | B55: 0.02579 | C55: =SUM(D55:XEG55) -> 8794.1815 | P55: =IF((OFFSET(Q$63,,$A$63)-1)>$C$17,0,$B$55*P56) -> 381.692 | AB55: =IF((OFFSET(AC$63,,$A$63)-1)>$C$17,0,$B$55*AB56) -> 496.87808 | AN55: =IF((OFFSET(AO$63,,$A$63)-1)>$C$17,0,$B$55*AN56) -> 610.34382 | AZ55: =IF((OFFSET(BA$63,,$A$63)-1)>$C$17,0,$B$55*AZ56) -> 722.14607 | BL55: =IF((OFFSET(BM$63,,$A$63)-1)>$C$17,0,$B$55*BL56) -> 832.34038 | BX55: =IF((OFFSET(BY$63,,$A$63)-1)>$C$17,0,$B$55*BX56) -> 940.98095 | CJ55: =IF((OFFSET(CK$63,,$A$63)-1)>$C$17,0,$B$55*CJ56) -> 1048.1208 | CV55: =IF((OFFSET(CW$63,,$A$63)-1)>$C$17,0,$B$55*CV56) -> 1153.8115 | DH55: =IF((OFFSET(DI$63,,$A$63)-1)>$C$17,0,$B$55*DH56) -> 1258.1037 | DT55: =IF((OFFSET(DU$63,,$A$63)-1)>$C$17,0,$B$55*DT56) -> 1349.7642 | EF55: =IF((OFFSET(EG$63,,$A$63)-1)>$C$17,0,$B$55*EF56) -> 0 | ER55: =IF((OFFSET(ES$63,,$A$63)-1)>$C$17,0,$B$55*ER56) -> 0 | FD55: =IF((OFFSET(FE$63,,$A$63)-1)>$C$17,0,$B$55*FD56) -> 0 | FP55: =IF((OFFSET(FQ$63,,$A$63)-1)>$C$17,0,$B$55*FP56) -> 0 | GB55: =IF((OFFSET(GC$63,,$A$63)-1)>$C$17,0,$B$55*GB56) -> 0 | GN55: =IF((OFFSET(GO$63,,$A$63)-1)>$C$17,0,$B$55*GN56) -> 0 | GZ55: =IF((OFFSET(HA$63,,$A$63)-1)>$C$17,0,$B$55*GZ56) -> 0 | HL55: =IF((OFFSET(HM$63,,$A$63)-1)>$C$17,0,$B$55*HL56) -> 0 | HX55: =IF((OFFSET(HY$63,,$A$63)-1)>$C$17,0,$B$55*HX56) -> 0 | IJ55: =IF((OFFSET(IK$63,,$A$63)-1)>$C$17,0,$B$55*IJ56) -> 0 | IV55: =IF((OFFSET(IW$63,,$A$63)-1)>$C$17,0,$B$55*IV56) -> 0
D56: =+D49 -> 10000 | E56: =+E49+D56 -> 10400 | F56: =+F49+E56 -> 10800 | G56: =+G49+F56 -> 11200 | H56: =+H49+G56 -> 11600 | I56: =+I49+H56 -> 12000 | J56: =+J49+I56 -> 12400 | K56: =+K49+J56 -> 12800 | L56: =+L49+K56 -> 13200 | ... P56: =+P49+O56 -> 14800 | Q56: =+Q49+P56-P55 -> 14822.308 | R56: =+R49+Q56-Q55 -> 15226.308 | S56: =+S49+R56-R55 -> 15630.308 | T56: =+T49+S56-S55 -> 16034.308 | U56: =+U49+T56-T55 -> 16438.308 | V56: =+V49+U56-U55 -> 16842.308 | W56: =+W49+V56-V55 -> 17246.308 | X56: =+X49+W56-W55 -> 17650.308 | ... IV56: =+IV49+IU56-IU55 -> 50986.965
...

Sheet Résumé
F1: Variables
F2: Non Fondateur
F3: 10 | G3: Durée de souscription
F4: 50 | G4: NB de part(s) initiale(s)
F5: 2 | G5: =+IF(F5=0,"","NB de part(s) récurrente(s) durant "&Détails!B63&" année(s)") -> NB de part(s) récurrente(s) durant 7,41666666666667 année(s)
B6: Simulation de placement - SCPI Fair Invest | F6: Oui | G6: Réinvestissement des loyers
B7: (éléments à titre indicatifs qui n'ont aucune valeur contractuelle) | F7: 0.0472 | G7: DVM
B8: Versement initial | C8: =+F4*Détails!C26 -> 10100 | F8: 0.01 | G8: Revalorisation des parts
B9: Versements mensuels | C9: =F5*Détails!C26 -> 404
B10: Durée du placement | C10: =Détails!C32 -> 10 | F10: TRI (Avec réinvestissement des loyers) | G10: 3 | H10: 4 | I10: 5 | J10: 6 | K10: 7 | L10: 8
B11: Versements cumulés * | C11: =+Détails!C49 -> 46803.789 | G11: =+Détails!J32 -> #REF! | H11: =+Détails!K32 -> #REF! | I11: =+Détails!L32 -> #REF! | J11: =+Détails!M32 -> #REF! | K11: =+Détails!N32 -> #REF! | L11: =+Détails!O32 -> 0.034366289
B12: Placements cumulés (loyers réinvestis) * | C12: =+Détails!C53 -> 56487.232 | G12: 9 | H12: 10 | I12: 11 | J12: 12 | K12: 13 | L12: 14
B13: Pour des raisons de performance, l'achat programmé de parts est interrompu après | C13: =+(C10*12-Détails!A63)/12 -> 7.4166667 | G13: =+Détails!P32 -> 0.038743731 | H13: =+Détails!Q32 -> 0.041718391 | I13: =+Détails!R32 -> 0.043862954 | J13: =+Détails!S32 -> 0.045453891 | K13: =+Détails!T32 -> 0.046663108 | L13: =+Détails!U32 -> 0.047588769
B14: Soit nombre de parts | C14: =C12/Détails!C26 -> 279.63976 | G14: 15 | H14: 16 | I14: 17 | J14: 18 | K14: 19 | L14: 20
B15: Rendement espéré** | C15: =Détails!C34 -> 0.0472 | G15: =+Détails!V32 -> 0.048321977 | H15: =+Détails!W32 -> 0.048901322 | I15: =+Détails!X32 -> 0.04936147 | J15: =+Détails!Y32 -> 0.046696177 | K15: =+Détails!Z32 -> 0.045964125 | L15: =+Détails!AA32 -> 0.045416412
B16: Loyers trimestriels | C16: =+Détails!L66*3 -> 119.18 | G16: 21
B17: Revenus cumulés (soumis à impôt)** | C17: =+Détails!J27-C18 -> 19978.735 | G17: =+Détails!AB32 -> 0.045060536
B18: Frais de souscription (10%HT) | C18: =-(C14*Détails!C28) -> -5592.7953
B19: Capital réel | C19: =+C12+C18 -> 50894.437
B20: Valeur à la sortie (avec revalorisation des parts)** | C20: =+Détails!C53+Détails!C65 -> 70873.172 | E20: =C20*(F7/12) -> 278.76781
B22: En laissant ces fonds sur un compte courant, vous auriez atteint à terme un capital de : | C22: =+C11-Détails!C55 -> 40644.979
F23: GAINS (Avec réinvestissement des loyers) | G23: 3 | H23: 4 | I23: 5 | J23: 6 | K23: 7 | L23: 8
G24: =+Détails!J35 -> #REF! | H24: =+Détails!K35 -> #REF! | I24: =+Détails!L35 -> #REF! | J24: =+Détails!M35 -> #REF! | K24: =+Détails!N35 -> #REF! | L24: =+Détails!O35 -> 8854.3553
B25: * L'achat des parts pendant la durée du placement est effectué aux prix des parts revalorisées au moment de l'achat. ** Ces informations sont données à titre indicatif, elles n'ont rien de définitif ni contractuel. Les performances passées ne préjugent pas des performances futures. Risque de perte en capital : Le capital investi dans la SCPI ne bénéficie d’aucune garantie ni protection. La valorisation du capital dépendra de la valorisation des biens immobiliers détenus par la SCPI dont vous détenez des parts. Revenus non garantis : Les revenus de la SCPI proviennent essentiellement des loyers encaissés et ne sont en conséquence pas garantis, même si la multitude des locataires permet de réduire sensiblement ce risque. Placement peu liquide : Ce placement est considéré comme peu liquide. La société de gestion ne peut garantir ni le retrait, ni la vente des parts, ni leur remboursement. Un marché secondaire permettant aux investisseurs de revendre leurs parts à d’autres investisseurs est en général organisé mais la revente de parts de SCPI reste, à titre de comparaison, plus difficile que la revente d’actions ou de parts d’OPCVM. Par ailleurs, lorsque vous achetez des parts de SCPI, vous payez un prix de souscription comportant un ensemble de frais fixes non négociables d’environ 10%. Cela signifie que si vous revendez vos parts le lendemain de votre investissement, vous perdrez 10%. C’est la raison pourquoi il est recommandé d’envisager une durée d’investissement relativement longue (plus de 5 ans). | G25: 9 | H25: 10 | I25: 11 | J25: 12 | K25: 13 | L25: 14
G26: =+Détails!P35 -> 12223.619 | H26: =+Détails!Q35 -> 15605.198 | I26: =+Détails!R35 -> 18999.278 | J26: =+Détails!S35 -> 22406.046 | K26: =+Détails!T35 -> 25825.692 | L26: =+Détails!U35 -> 29258.411
G27: 15 | H27: 16 | I27: 17 | J27: 18 | K27: 19 | L27: 20
G28: =+Détails!V35 -> 32704.397 | H28: =+Détails!W35 -> 36163.85 | I28: =+Détails!X35 -> 39636.971 | J28: =+Détails!Y35 -> 40790.485 | K28: =+Détails!Z35 -> 46235.894 | L28: =+Détails!AA35 -> 53124.883
G29: 21
G30: =+Détails!AB35 -> 61607.739
F33: Valeur à la sortie (Avec réinvestissement des loyers) | G33: 3 | H33: 4 | I33: 5 | J33: 6 | K33: 7 | L33: 8
G34: =+Détails!J38 -> #REF! | H34: =+Détails!K38 -> #REF! | I34: =+Détails!L38 -> #REF! | J34: =+Détails!M38 -> #REF! | K34: =+Détails!N38 -> #REF! | L34: =+Détails!O38 -> 56224.417
G35: 9 | H35: 10 | I35: 11 | J35: 12 | K35: 13 | L35: 14
G36: =+Détails!P38 -> 59593.681 | H36: =+Détails!Q38 -> 62975.26 | I36: =+Détails!R38 -> 66369.34 | J36: =+Détails!S38 -> 69776.108 | K36: =+Détails!T38 -> 73195.754 | L36: =+Détails!U38 -> 76628.473
G37: 15 | H37: 16 | I37: 17 | J37: 18 | K37: 19 | L37: 20
G38: =+Détails!V38 -> 80074.459 | H38: =+Détails!W38 -> 83533.912 | I38: =+Détails!X38 -> 87007.033 | J38: =+Détails!Y38 -> 94335.431 | K38: =+Détails!Z38 -> 112131.98 | L38: =+Détails!AA38 -> 131376.21
G39: 21
G40: =+Détails!AB38 -> 152221.15
A53: SAS ConexCap Finance au capital de 120 000 € - SIREN 529 861 445 R.C.S.Paris - NAF 7022 Z Conseil en Investissement Financier – membre de la CNCIF (association agréée par l’AMF) Courtier IOBSP, immatriculé ORIAS n° 11063271, www.orias.fr, « Sous le contrôle de l’ACPR, 61 rue Taitbout, 75346 Paris Cedex 9 » Plus d'informations sur les Mentions Légales sur www.570easi.com
