Workbook

Sheet Investissements 1ère année
C1: Unité | D1: PU | E1: Quantité | F1: Total
B2: Achat de la ferme | C2: Ferme | D2: 46500000 | E2: 1 | F2: =E2*D2 -> 46500000 | G2: 45 000 000 + frais
B3: Améliorations à apporter à l'oliveraie existante
B4: Taille oliviers | C4: Arbres | D4: 110 | E4: 8000 | F4: =E4*D4 -> 880000
B5: Travail du sol | C5: ha | D5: 15000 | E5: 55 | F5: =E5*D5 -> 825000
B6: GàG | C6: KM | D6: =23*1000 -> 23000 | E6: 41 | F6: =E6*D6 -> 943000
B7: Goutteurs auto régulant+filtre | C7: Unité | D7: 18 | E7: 16000 | F7: =E7*D7 -> 288000
B8: Station de fertirrigation | C8: Unité | D8: 300000 | E8: 1 | F8: =E8*D8 -> 300000
B9: Brise vent + GàG | C9: M | D9: 100 | E9: 3900 | F9: =E9*D9 -> 390000
B10: Fumier | C10: M3 | D10: 6000 | E10: 56 | F10: =E10*D10 -> 336000
B11: Traitement | D11: 2000000 | E11: 1 | F11: =E11*D11 -> 2000000
B12: Engrais | D12: 2000000 | E12: 1 | F12: =E12*D12 -> 2000000
B13: Total | F13: =SUM(F4:F12) -> 7962000
B14: Total | F14: =SUM(F4:F12,F2) -> 54462000
G15: =F4+F5+F10+F11+F12 -> 6041000
B17: Frais d'exploitation
B18: Masse salariale | C18: Unité | D18: 500000 | E18: 12 | F18: =E18*D18 -> 6000000
B19: Manutention / Cueillette | C19: J | D19: 20000 | E19: 15 | F19: =E19*D19 -> 300000 | G19: Périodique
B20: Location engins | C20: Ha | D20: 15000 | E20: 50 | F20: =E20*D20 -> 750000 | G20: Périodique
B21: Casoral | C21: 1 | F21: 150000
B22: Comptable | C22: mois | D22: 20000 | E22: 12 | F22: =D22*E22 -> 240000
B23: Bureau d'études | C23: Ha | D23: 25000 | E23: 55 | F23: =E23*D23 -> 1375000
B24: Total | F24: =SUM(F18:F23) -> 8815000
B26: Total 1ère année | F26: =F14+F18+F19+F20+F21+F22+F23 -> 63277000

Sheet Chiffre d'affaire 
A2: CA 1ère année
B3: Unité | C3: PU | D3: Quantités | E3: Total
A4: Olive de table | B4: T | C4: =200*1000 -> 200000 | D4: 60 | E4: =D4*C4 -> 12000000 | F4: à raison de 15 Kg /Olivier moyen
A5: Olive pour pressage | B5: T | C5: =125*1000 -> 125000 | D5: 60 | E5: =D5*C5 -> 7500000 | F5: à raison de 15 Kg /Olivier moyen
A6: Luzerne | B6: Botte | C6: 600 | D6: 6000 | E6: =D6*C6 -> 3600000 | F6: à raison de 750 bottes/ mois à partir de Mars
A7: Céréales (Blé Tendre) | B7: Qx | C7: 5000 | D7: 200 | E7: =D7*C7 -> 1000000
A8: Paille céréales | B8: Bottes | C8: 700 | D8: 2000 | E8: =D8*C8 -> 1400000
E9: =SUM(E4:E8) -> 25500000
A11: CA 2ème année
B12: Unité | C12: PU | D12: Quantités | E12: Total
A13: Olive de table | B13: T | C13: =200*1000 -> 200000 | D13: =D4*1.3 -> 78 | E13: =D13*C13 -> 15600000
A14: Olive pour pressage | B14: T | C14: =125*1000 -> 125000 | D14: =D5*1.3 -> 78 | E14: =D14*C14 -> 9750000
A15: Luzerne | B15: Botte | C15: 700 | D15: 9000 | E15: =D15*C15 -> 6300000
E16: =SUM(E13:E15) -> 31650000
A19: CA 3ème année
B20: Unité | C20: PU | D20: Quantités | E20: Total
A21: Olive de table | B21: T | C21: =200*1000 -> 200000 | D21: =D13*1.2 -> 93.6 | E21: =D21*C21 -> 18720000
A22: Olive pour pressage | B22: T | C22: =125*1000 -> 125000 | D22: =D14*1.2 -> 93.6 | E22: =D22*C22 -> 11700000
A23: Luzerne | B23: Botte | C23: 750 | D23: 9000 | E23: =D23*C23 -> 6750000
E24: =SUM(E21:E23) -> 37170000
A27: CA 4ème année
B28: Unité | C28: PU | D28: Quantités | E28: Total
A29: Olive de table | B29: T | C29: =200*1000 -> 200000 | D29: =D21*1.2 -> 112.32 | E29: =D29*C29 -> 22464000
A30: Olive pour pressage | B30: T | C30: =125*1000 -> 125000 | D30: =D22*1.2 -> 112.32 | E30: =D30*C30 -> 14040000
A31: Luzerne | B31: Botte | C31: 750 | D31: =9000*1.2 -> 10800 | E31: =D31*C31 -> 8100000
E32: =SUM(E29:E31) -> 44604000
C37: Olive de table | D37: Olive pour pressage | E37: Luzerne | F37: Céréales | G37: Paille céréales
B38: Unité | C38: T | D38: T | E38: Botte | F38: Qx | G38: Bottes
A39: A1 | B39: PU | C39: =200*1000 -> 200000 | D39: =125*1000 -> 125000 | E39: 600 | F39: 5000 | G39: 700
B40: Quantités | C40: 60 | D40: 60 | E40: 6000 | F40: 200 | G40: 2000
B41: Total A1 | C41: =C39*C40 -> 12000000 | D41: =D39*D40 -> 7500000 | E41: =E39*E40 -> 3600000 | F41: =F39*F40 -> 1000000 | G41: =G39*G40 -> 1400000 | H41: =SUM(C41:G41) -> 25500000
A42: A2 | B42: PU | C42: =200*1000 -> 200000 | D42: =125*1000 -> 125000 | E42: 700 | F42: 0 | G42: 0
B43: Quantités | C43: =D13 -> 78 | D43: =D14 -> 78 | E43: 9000 | F43: 0 | G43: 0
B44: Total A2 | C44: =C43*C42 -> 15600000 | D44: =D43*D42 -> 9750000 | E44: =E43*E42 -> 6300000 | F44: 0 | G44: 0 | H44: =SUM(C44:G44) -> 31650000
A45: A3 | B45: PU | C45: =200*1000 -> 200000 | D45: =125*1000 -> 125000 | E45: 750 | F45: 0 | G45: 0
B46: Quantités | C46: 93.6 | D46: 93.6 | E46: 9000 | F46: 0 | G46: 0
B47: Total A2 | C47: =C45*C46 -> 18720000 | D47: =D45*D46 -> 11700000 | E47: =E45*E46 -> 6750000 | F47: 0 | G47: 0 | H47: =SUM(C47:G47) -> 37170000
A48: A4 | B48: PU | C48: 200000 | D48: 125000 | E48: 750 | F48: 0 | G48: 0
B49: Quantités | C49: 112.32 | D49: 112.32 | E49: 10800 | F49: 0 | G49: 0
B50: Total A3 | C50: =C48*C49 -> 22464000 | D50: =D48*D49 -> 14040000 | E50: =E48*E49 -> 8100000 | F50: 0 | G50: 0 | H50: =SUM(C50:G50) -> 44604000
...

Sheet Amortissements
B1: A0 | C1: A1 | D1: A2 | E1: A3 | F1: A4 | G1: A5
A2: Frais d'exploitation | B2: ='Investissements 1ère année'!F24 -> 8815000 | C2: =B2*1.05 -> 9255750 | D2: =C2*1.05 -> 9718537.5 | E2: =D2*1.05 -> 10204464 | F2: =E2*1.05 -> 10714688 | G2: =F2*1.05 -> 11250422
A3: Fournitures | B3: ='Investissements 1ère année'!F13 -> 7962000 | C3: ='Investissements 1ère année'!$G$15 -> 6041000 | D3: ='Investissements 1ère année'!$G$15 -> 6041000 | E3: ='Investissements 1ère année'!$G$15 -> 6041000 | F3: ='Investissements 1ère année'!$G$15 -> 6041000 | G3: ='Investissements 1ère année'!$G$15 -> 6041000
A4: Autres frais | B4: 500000 | C4: 500000 | D4: 500000 | E4: 500000 | F4: 500000 | G4: 500000
A5: Total Frais | B5: =SUM(B2:B4) -> 17277000 | C5: =SUM(C2:C4) -> 15796750 | D5: =SUM(D2:D4) -> 16259538 | E5: =SUM(E2:E4) -> 16745464 | F5: =SUM(F2:F4) -> 17255688 | G5: =SUM(G2:G4) -> 17791422
A6: Chiffre d'affaire | C6: ='Chiffre d''affaire '!H41 -> 25500000 | D6: ='Chiffre d''affaire '!H44 -> 31650000 | E6: ='Chiffre d''affaire '!H47 -> 37170000 | F6: ='Chiffre d''affaire '!H50 -> 44604000 | G6: ='Chiffre d''affaire '!H53 -> 57175200 | H6: =SUM(C6:G6) -> 196099200
A7: Revenu Net | C7: =C6-C5 -> 9703250 | D7: =D6-D5 -> 15390462 | E7: =E6-E5 -> 20424536 | F7: =F6-F5 -> 27348312 | G7: =G6-G5 -> 39383778 | H7: =SUM(C7:G7) -> 1.1225034e+08
C8: =C7/$B$12 -> 0.15334561 | D8: =D7/$B$12 -> 0.24322364 | E8: =E7/$B$12 -> 0.32277977 | F8: =F7/$B$12 -> 0.43219989 | G8: =G7/$B$12 -> 0.62240274
C9: =C7/$B$12 -> 0.15334561 | D9: =D7/$B$12 -> 0.24322364 | E9: =E7/$B$12 -> 0.32277977 | F9: =F7/$B$12 -> 0.43219989 | G9: =G7/$B$12 -> 0.62240274
A11: Période | B11: 5 ans
A12: Investissement de départ | B12: ='Investissements 1ère année'!F26 -> 63277000
A13: CAGR 5 ans | B13: 0.2289 | D13: =+B13/$E$19 -> 0.0009156
A14: VAN | D14: =+B14/$E$19 -> 0
A15: Taux d'actualisation | B15: 0.05
A16: VAN | B16: =NPV(B15,E26:E30)+E25 -> 35117510
A17: TRI | B17: =IRR(E25:E30) -> 0.19295632
A18: Indice de profitabilité | B18: =1+(B16/B12) -> 1.5549806
D19: 1 | E19: 250
A23: Calcul VAN
A24: Année | B24: Investissement | C24: Total Frais | D24: Chiffre d'affaire | E24: Revenu Net
A25: 0 | B25: ='Investissements 1ère année'!F2 -> 46500000 | C25: 17277000 | D25: 0 | E25: =+D25-C25-B25 -> -63777000
A26: 1 | C26: 15796750 | D26: 25500000 | E26: =+D26-C26-B26 -> 9703250
A27: 2 | C27: 16259538 | D27: 31650000 | E27: =+D27-C27-B27 -> 15390462
A28: 3 | C28: 16745464 | D28: 39705000 | E28: =+D28-C28-B28 -> 22959536
A29: 4 | C29: 17255688 | D29: 47646000 | E29: =+D29-C29-B29 -> 30390312
A30: 5 | C30: 17791422 | D30: 57175200 | E30: =+D30-C30-B30 -> 39383778
A33: ROI | B33: =((H7-B12)/B12)*100% -> 0.77395165
